Workbook

Sheet Генераторы
A1: Название генератора | B1: Очки Энергии | C1: Бросок на защиту щита | D1: Изменение манёвренности | E1: Дополнительные свойства | F1: Совместимость двигателей | G1: Стоимость реквизиций
A2: SG-2KT | B2: 10 | C2: 3+ | D2: 2 | E2: - | F2: Серия LQ-B | G2: 10
A3: SG-3KT | B3: 15 | C3: 3+ | D3: 3 | E3: - | F3: Серия LQ-B | G3: 20
A4: SG-8KT | B4: 20 | C4: 4+ | D4: 8 | E4: - | F4: Серия LQ-B | G4: 30

Sheet Двигатели
A1: Название двигателя | B1: Потребление энергии | C1: Общий запас манёвренности | D1: Дополнительные свойства | E1: Стоимость реквизиций
A2: LQB-S | B2: 3 | C2: 16 | D2: - | E2: 24
A3: LQB-M | B3: 6 | C3: 18 | D3: - | E3: 32
A4: LQB-L | B4: 10 | C4: 20 | D4: - | E4: 40

Sheet Орудия
A1: Название орудия | B1: Тип снаряда | C1: Потребление энергии | D1: Изменение манёвренности | E1: Дальность стрельбы | F1: Дополнительные свойства | G1: Стоимость реквизиций
A2: HRP "Зевс" | B2: Кристалл | C2: 10 | D2: 5 | E2: 15/25'
A3: BT "Молот" | B3: Болт | C3: 4 | D3: 4 | E3: 12/24'
A4: MT-M "Орган" | B4: ракета | C4: 3 | D4: 4 | E4: 8/18'
A5: RP "Рейкастер" | B5: Кристалл | C5: 4 | D5: 4 | E5: 8/16'
A6: HBT "Рубрик" | B6: тяж. Болт | C6: 10 | D6: 5 | E6: 18/32'
A7: MT-L "сверчок" | B7: Лёгкая ракета | C7: 2 | D7: 3 | E7: 8/18'
A8: FTLW "Смайт" | B8: FTL-болт | C8: 14 | D8: 8 | E8: -/40'
A9: BT-D спаренный "молот" | B9: Болт | C9: 8 | D9: 5 | E9: 12/24'

Sheet Снаряды
A1: Название снаряда | B1: Тип | C1: Точность | D1: Урон | E1: Свойства | F1: Стоимость реквизиций

Sheet Модули
A1: Название модуля | B1: Тип | C1: Потребление энергии | D1: Изменение манёвренности | E1: Особые свойства | F1: Стоимость реквизиций

Sheet Сводная таблица базовых констру
A1: Название генератора | B1: Очки Энергии генератора | C1: Бросок на защиту щита | D1: Изменение манёвренности генератора | E1: Название двигателя | F1: Потребление энергии Двигателя | G1: Общий запас манёвренности двигателя | H1: Название орудия | I1: Тип снаряда | J1: Потребление энергии орудия | K1: Изменение манёвренности орудия | L1: Дальность стрельбы орудия | M1: Итоговая энергия | N1: Итоговая манёвренность
A2: =Генераторы!A$2 -> SG-2KT | B2: =Генераторы!B$2 -> 10 | C2: =Генераторы!C$2 -> 3+ | D2: =Генераторы!D$2 -> 2 | E2: =Двигатели!A$2 -> LQB-S | F2: =Двигатели!B$2 -> 3 | G2: =Двигатели!C$2 -> 16 | H2: =Орудия!A$2 -> HRP "Зевс" | I2: =Орудия!B$2 -> Кристалл | J2: =Орудия!C$2 -> 10 | K2: =Орудия!D$2 -> 5 | L2: =Орудия!E$2 -> 15/25' | M2: =B2-F2-J2 -> -3 | N2: =G2-D2-K2 -> 9
A3: =Генераторы!A$3 -> SG-3KT | B3: =Генераторы!B$3 -> 15 | C3: =Генераторы!C$3 -> 3+ | D3: =Генераторы!D$3 -> 3 | E3: =Двигатели!A$2 -> LQB-S | F3: =Двигатели!B$2 -> 3 | G3: =Двигатели!C$2 -> 16 | H3: =Орудия!A$2 -> HRP "Зевс" | I3: =Орудия!B$2 -> Кристалл | J3: =Орудия!C$2 -> 10 | K3: =Орудия!D$2 -> 5 | L3: =Орудия!E$2 -> 15/25' | M3: =B3-F3-J3 -> 2 | N3: =G3-D3-K3 -> 8
A4: =Генераторы!A$4 -> SG-8KT | B4: =Генераторы!B$4 -> 20 | C4: =Генераторы!C$4 -> 4+ | D4: =Генераторы!D$4 -> 8 | E4: =Двигатели!A$2 -> LQB-S | F4: =Двигатели!B$2 -> 3 | G4: =Двигатели!C$2 -> 16 | H4: =Орудия!A$2 -> HRP "Зевс" | I4: =Орудия!B$2 -> Кристалл | J4: =Орудия!C$2 -> 10 | K4: =Орудия!D$2 -> 5 | L4: =Орудия!E$2 -> 15/25' | M4: =B4-F4-J4 -> 7 | N4: =G4-D4-K4 -> 3
A5: =Генераторы!A$2 -> SG-2KT | B5: =Генераторы!B$2 -> 10 | C5: =Генераторы!C$2 -> 3+ | D5: =Генераторы!D$2 -> 2 | E5: =Двигатели!A$3 -> LQB-M | F5: =Двигатели!B$3 -> 6 | G5: =Двигатели!C$3 -> 18 | H5: =Орудия!A$2 -> HRP "Зевс" | I5: =Орудия!B$2 -> Кристалл | J5: =Орудия!C$2 -> 10 | K5: =Орудия!D$2 -> 5 | L5: =Орудия!E$2 -> 15/25' | M5: =B5-F5-J5 -> -6 | N5: =G5-D5-K5 -> 11
A6: =Генераторы!A$3 -> SG-3KT | B6: =Генераторы!B$3 -> 15 | C6: =Генераторы!C$3 -> 3+ | D6: =Генераторы!D$3 -> 3 | E6: =Двигатели!A$3 -> LQB-M | F6: =Двигатели!B$3 -> 6 | G6: =Двигатели!C$3 -> 18 | H6: =Орудия!A$2 -> HRP "Зевс" | I6: =Орудия!B$2 -> Кристалл | J6: =Орудия!C$2 -> 10 | K6: =Орудия!D$2 -> 5 | L6: =Орудия!E$2 -> 15/25' | M6: =B6-F6-J6 -> -1 | N6: =G6-D6-K6 -> 10
A7: =Генераторы!A$4 -> SG-8KT | B7: =Генераторы!B$4 -> 20 | C7: =Генераторы!C$4 -> 4+ | D7: =Генераторы!D$4 -> 8 | E7: =Двигатели!A$3 -> LQB-M | F7: =Двигатели!B$3 -> 6 | G7: =Двигатели!C$3 -> 18 | H7: =Орудия!A$2 -> HRP "Зевс" | I7: =Орудия!B$2 -> Кристалл | J7: =Орудия!C$2 -> 10 | K7: =Орудия!D$2 -> 5 | L7: =Орудия!E$2 -> 15/25' | M7: =B7-F7-J7 -> 4 | N7: =G7-D7-K7 -> 5
A8: =Генераторы!A$2 -> SG-2KT | B8: =Генераторы!B$2 -> 10 | C8: =Генераторы!C$2 -> 3+ | D8: =Генераторы!D$2 -> 2 | E8: =Двигатели!A$4 -> LQB-L | F8: =Двигатели!B$4 -> 10 | G8: =Двигатели!C$4 -> 20 | H8: =Орудия!A$2 -> HRP "Зевс" | I8: =Орудия!B$2 -> Кристалл | J8: =Орудия!C$2 -> 10 | K8: =Орудия!D$2 -> 5 | L8: =Орудия!E$2 -> 15/25' | M8: =B8-F8-J8 -> -10 | N8: =G8-D8-K8 -> 13
A9: =Генераторы!A$3 -> SG-3KT | B9: =Генераторы!B$3 -> 15 | C9: =Генераторы!C$3 -> 3+ | D9: =Генераторы!D$3 -> 3 | E9: =Двигатели!A$4 -> LQB-L | F9: =Двигатели!B$4 -> 10 | G9: =Двигатели!C$4 -> 20 | H9: =Орудия!A$2 -> HRP "Зевс" | I9: =Орудия!B$2 -> Кристалл | J9: =Орудия!C$2 -> 10 | K9: =Орудия!D$2 -> 5 | L9: =Орудия!E$2 -> 15/25' | M9: =B9-F9-J9 -> -5 | N9: =G9-D9-K9 -> 12
A10: =Генераторы!A$4 -> SG-8KT | B10: =Генераторы!B$4 -> 20 | C10: =Генераторы!C$4 -> 4+ | D10: =Генераторы!D$4 -> 8 | E10: =Двигатели!A$4 -> LQB-L | F10: =Двигатели!B$4 -> 10 | G10: =Двигатели!C$4 -> 20 | H10: =Орудия!A$2 -> HRP "Зевс" | I10: =Орудия!B$2 -> Кристалл | J10: =Орудия!C$2 -> 10 | K10: =Орудия!D$2 -> 5 | L10: =Орудия!E$2 -> 15/25' | M10: =B10-F10-J10 -> 0 | N10: =G10-D10-K10 -> 7
A11: =Генераторы!A$2 -> SG-2KT | B11: =Генераторы!B$2 -> 10 | C11: =Генераторы!C$2 -> 3+ | D11: =Генераторы!D$2 -> 2 | E11: =Двигатели!A$2 -> LQB-S | F11: =Двигатели!B$2 -> 3 | G11: =Двигатели!C$2 -> 16 | H11: =Орудия!A$3 -> BT "Молот" | I11: =Орудия!B$3 -> Болт | J11: =Орудия!C$3 -> 4 | K11: =Орудия!D$3 -> 4 | L11: =Орудия!E$3 -> 12/24' | M11: =B11-F11-J11 -> 3 | N11: =G11-D11-K11 -> 10
A12: =Генераторы!A$3 -> SG-3KT | B12: =Генераторы!B$3 -> 15 | C12: =Генераторы!C$3 -> 3+ | D12: =Генераторы!D$3 -> 3 | E12: =Двигатели!A$2 -> LQB-S | F12: =Двигатели!B$2 -> 3 | G12: =Двигатели!C$2 -> 16 | H12: =Орудия!A$3 -> BT "Молот" | I12: =Орудия!B$3 -> Болт | J12: =Орудия!C$3 -> 4 | K12: =Орудия!D$3 -> 4 | L12: =Орудия!E$3 -> 12/24' | M12: =B12-F12-J12 -> 8 | N12: =G12-D12-K12 -> 9
A13: =Генераторы!A$4 -> SG-8KT | B13: =Генераторы!B$4 -> 20 | C13: =Генераторы!C$4 -> 4+ | D13: =Генераторы!D$4 -> 8 | E13: =Двигатели!A$2 -> LQB-S | F13: =Двигатели!B$2 -> 3 | G13: =Двигатели!C$2 -> 16 | H13: =Орудия!A$3 -> BT "Молот" | I13: =Орудия!B$3 -> Болт | J13: =Орудия!C$3 -> 4 | K13: =Орудия!D$3 -> 4 | L13: =Орудия!E$3 -> 12/24' | M13: =B13-F13-J13 -> 13 | N13: =G13-D13-K13 -> 4
A14: =Генераторы!A$2 -> SG-2KT | B14: =Генераторы!B$2 -> 10 | C14: =Генераторы!C$2 -> 3+ | D14: =Генераторы!D$2 -> 2 | E14: =Двигатели!A$3 -> LQB-M | F14: =Двигатели!B$3 -> 6 | G14: =Двигатели!C$3 -> 18 | H14: =Орудия!A$3 -> BT "Молот" | I14: =Орудия!B$3 -> Болт | J14: =Орудия!C$3 -> 4 | K14: =Орудия!D$3 -> 4 | L14: =Орудия!E$3 -> 12/24' | M14: =B14-F14-J14 -> 0 | N14: =G14-D14-K14 -> 12
A15: =Генераторы!A$3 -> SG-3KT | B15: =Генераторы!B$3 -> 15 | C15: =Генераторы!C$3 -> 3+ | D15: =Генераторы!D$3 -> 3 | E15: =Двигатели!A$3 -> LQB-M | F15: =Двигатели!B$3 -> 6 | G15: =Двигатели!C$3 -> 18 | H15: =Орудия!A$3 -> BT "Молот" | I15: =Орудия!B$3 -> Болт | J15: =Орудия!C$3 -> 4 | K15: =Орудия!D$3 -> 4 | L15: =Орудия!E$3 -> 12/24' | M15: =B15-F15-J15 -> 5 | N15: =G15-D15-K15 -> 11
A16: =Генераторы!A$4 -> SG-8KT | B16: =Генераторы!B$4 -> 20 | C16: =Генераторы!C$4 -> 4+ | D16: =Генераторы!D$4 -> 8 | E16: =Двигатели!A$3 -> LQB-M | F16: =Двигатели!B$3 -> 6 | G16: =Двигатели!C$3 -> 18 | H16: =Орудия!A$3 -> BT "Молот" | I16: =Орудия!B$3 -> Болт | J16: =Орудия!C$3 -> 4 | K16: =Орудия!D$3 -> 4 | L16: =Орудия!E$3 -> 12/24' | M16: =B16-F16-J16 -> 10 | N16: =G16-D16-K16 -> 6
A17: =Генераторы!A$2 -> SG-2KT | B17: =Генераторы!B$2 -> 10 | C17: =Генераторы!C$2 -> 3+ | D17: =Генераторы!D$2 -> 2 | E17: =Двигатели!A$4 -> LQB-L | F17: =Двигатели!B$4 -> 10 | G17: =Двигатели!C$4 -> 20 | H17: =Орудия!A$3 -> BT "Молот" | I17: =Орудия!B$3 -> Болт | J17: =Орудия!C$3 -> 4 | K17: =Орудия!D$3 -> 4 | L17: =Орудия!E$3 -> 12/24' | M17: =B17-F17-J17 -> -4 | N17: =G17-D17-K17 -> 14
A18: =Генераторы!A$3 -> SG-3KT | B18: =Генераторы!B$3 -> 15 | C18: =Генераторы!C$3 -> 3+ | D18: =Генераторы!D$3 -> 3 | E18: =Двигатели!A$4 -> LQB-L | F18: =Двигатели!B$4 -> 10 | G18: =Двигатели!C$4 -> 20 | H18: =Орудия!A$3 -> BT "Молот" | I18: =Орудия!B$3 -> Болт | J18: =Орудия!C$3 -> 4 | K18: =Орудия!D$3 -> 4 | L18: =Орудия!E$3 -> 12/24' | M18: =B18-F18-J18 -> 1 | N18: =G18-D18-K18 -> 13
A19: =Генераторы!A$4 -> SG-8KT | B19: =Генераторы!B$4 -> 20 | C19: =Генераторы!C$4 -> 4+ | D19: =Генераторы!D$4 -> 8 | E19: =Двигатели!A$4 -> LQB-L | F19: =Двигатели!B$4 -> 10 | G19: =Двигатели!C$4 -> 20 | H19: =Орудия!A$3 -> BT "Молот" | I19: =Орудия!B$3 -> Болт | J19: =Орудия!C$3 -> 4 | K19: =Орудия!D$3 -> 4 | L19: =Орудия!E$3 -> 12/24' | M19: =B19-F19-J19 -> 6 | N19: =G19-D19-K19 -> 8
A20: =Генераторы!A$2 -> SG-2KT | B20: =Генераторы!B$2 -> 10 | C20: =Генераторы!C$2 -> 3+ | D20: =Генераторы!D$2 -> 2 | E20: =Двигатели!A$2 -> LQB-S | F20: =Двигатели!B$2 -> 3 | G20: =Двигатели!C$2 -> 16 | H20: =Орудия!A$4 -> MT-M "Орган" | I20: =Орудия!B$4 -> ракета | J20: =Орудия!C$4 -> 3 | K20: =Орудия!D$4 -> 4 | L20: =Орудия!E$4 -> 8/18' | M20: =B20-F20-J20 -> 4 | N20: =G20-D20-K20 -> 10
A21: =Генераторы!A$3 -> SG-3KT | B21: =Генераторы!B$3 -> 15 | C21: =Генераторы!C$3 -> 3+ | D21: =Генераторы!D$3 -> 3 | E21: =Двигатели!A$2 -> LQB-S | F21: =Двигатели!B$2 -> 3 | G21: =Двигатели!C$2 -> 16 | H21: =Орудия!A$4 -> MT-M "Орган" | I21: =Орудия!B$4 -> ракета | J21: =Орудия!C$4 -> 3 | K21: =Орудия!D$4 -> 4 | L21: =Орудия!E$4 -> 8/18' | M21: =B21-F21-J21 -> 9 | N21: =G21-D21-K21 -> 9
A22: =Генераторы!A$4 -> SG-8KT | B22: =Генераторы!B$4 -> 20 | C22: =Генераторы!C$4 -> 4+ | D22: =Генераторы!D$4 -> 8 | E22: =Двигатели!A$2 -> LQB-S | F22: =Двигатели!B$2 -> 3 | G22: =Двигатели!C$2 -> 16 | H22: =Орудия!A$4 -> MT-M "Орган" | I22: =Орудия!B$4 -> ракета | J22: =Орудия!C$4 -> 3 | K22: =Орудия!D$4 -> 4 | L22: =Орудия!E$4 -> 8/18' | M22: =B22-F22-J22 -> 14 | N22: =G22-D22-K22 -> 4
A23: =Генераторы!A$2 -> SG-2KT | B23: =Генераторы!B$2 -> 10 | C23: =Генераторы!C$2 -> 3+ | D23: =Генераторы!D$2 -> 2 | E23: =Двигатели!A$3 -> LQB-M | F23: =Двигатели!B$3 -> 6 | G23: =Двигатели!C$3 -> 18 | H23: =Орудия!A$4 -> MT-M "Орган" | I23: =Орудия!B$4 -> ракета | J23: =Орудия!C$4 -> 3 | K23: =Орудия!D$4 -> 4 | L23: =Орудия!E$4 -> 8/18' | M23: =B23-F23-J23 -> 1 | N23: =G23-D23-K23 -> 12
A24: =Генераторы!A$3 -> SG-3KT | B24: =Генераторы!B$3 -> 15 | C24: =Генераторы!C$3 -> 3+ | D24: =Генераторы!D$3 -> 3 | E24: =Двигатели!A$3 -> LQB-M | F24: =Двигатели!B$3 -> 6 | G24: =Двигатели!C$3 -> 18 | H24: =Орудия!A$4 -> MT-M "Орган" | I24: =Орудия!B$4 -> ракета | J24: =Орудия!C$4 -> 3 | K24: =Орудия!D$4 -> 4 | L24: =Орудия!E$4 -> 8/18' | M24: =B24-F24-J24 -> 6 | N24: =G24-D24-K24 -> 11
A25: =Генераторы!A$4 -> SG-8KT | B25: =Генераторы!B$4 -> 20 | C25: =Генераторы!C$4 -> 4+ | D25: =Генераторы!D$4 -> 8 | E25: =Двигатели!A$3 -> LQB-M | F25: =Двигатели!B$3 -> 6 | G25: =Двигатели!C$3 -> 18 | H25: =Орудия!A$4 -> MT-M "Орган" | I25: =Орудия!B$4 -> ракета | J25: =Орудия!C$4 -> 3 | K25: =Орудия!D$4 -> 4 | L25: =Орудия!E$4 -> 8/18' | M25: =B25-F25-J25 -> 11 | N25: =G25-D25-K25 -> 6
A26: =Генераторы!A$2 -> SG-2KT | B26: =Генераторы!B$2 -> 10 | C26: =Генераторы!C$2 -> 3+ | D26: =Генераторы!D$2 -> 2 | E26: =Двигатели!A$4 -> LQB-L | F26: =Двигатели!B$4 -> 10 | G26: =Двигатели!C$4 -> 20 | H26: =Орудия!A$4 -> MT-M "Орган" | I26: =Орудия!B$4 -> ракета | J26: =Орудия!C$4 -> 3 | K26: =Орудия!D$4 -> 4 | L26: =Орудия!E$4 -> 8/18' | M26: =B26-F26-J26 -> -3 | N26: =G26-D26-K26 -> 14
A27: =Генераторы!A$3 -> SG-3KT | B27: =Генераторы!B$3 -> 15 | C27: =Генераторы!C$3 -> 3+ | D27: =Генераторы!D$3 -> 3 | E27: =Двигатели!A$4 -> LQB-L | F27: =Двигатели!B$4 -> 10 | G27: =Двигатели!C$4 -> 20 | H27: =Орудия!A$4 -> MT-M "Орган" | I27: =Орудия!B$4 -> ракета | J27: =Орудия!C$4 -> 3 | K27: =Орудия!D$4 -> 4 | L27: =Орудия!E$4 -> 8/18' | M27: =B27-F27-J27 -> 2 | N27: =G27-D27-K27 -> 13
A28: =Генераторы!A$4 -> SG-8KT | B28: =Генераторы!B$4 -> 20 | C28: =Генераторы!C$4 -> 4+ | D28: =Генераторы!D$4 -> 8 | E28: =Двигатели!A$4 -> LQB-L | F28: =Двигатели!B$4 -> 10 | G28: =Двигатели!C$4 -> 20 | H28: =Орудия!A$4 -> MT-M "Орган" | I28: =Орудия!B$4 -> ракета | J28: =Орудия!C$4 -> 3 | K28: =Орудия!D$4 -> 4 | L28: =Орудия!E$4 -> 8/18' | M28: =B28-F28-J28 -> 7 | N28: =G28-D28-K28 -> 8
A29: =Генераторы!A$2 -> SG-2KT | B29: =Генераторы!B$2 -> 10 | C29: =Генераторы!C$2 -> 3+ | D29: =Генераторы!D$2 -> 2 | E29: =Двигатели!A$2 -> LQB-S | F29: =Двигатели!B$2 -> 3 | G29: =Двигатели!C$2 -> 16 | H29: =Орудия!A$5 -> RP "Рейкастер" | I29: =Орудия!B$5 -> Кристалл | J29: =Орудия!C$5 -> 4 | K29: =Орудия!D$5 -> 4 | L29: =Орудия!E$5 -> 8/16' | M29: =B29-F29-J29 -> 3 | N29: =G29-D29-K29 -> 10
A30: =Генераторы!A$3 -> SG-3KT | B30: =Генераторы!B$3 -> 15 | C30: =Генераторы!C$3 -> 3+ | D30: =Генераторы!D$3 -> 3 | E30: =Двигатели!A$2 -> LQB-S | F30: =Двигатели!B$2 -> 3 | G30: =Двигатели!C$2 -> 16 | H30: =Орудия!A$5 -> RP "Рейкастер" | I30: =Орудия!B$5 -> Кристалл | J30: =Орудия!C$5 -> 4 | K30: =Орудия!D$5 -> 4 | L30: =Орудия!E$5 -> 8/16' | M30: =B30-F30-J30 -> 8 | N30: =G30-D30-K30 -> 9
A31: =Генераторы!A$4 -> SG-8KT | B31: =Генераторы!B$4 -> 20 | C31: =Генераторы!C$4 -> 4+ | D31: =Генераторы!D$4 -> 8 | E31: =Двигатели!A$2 -> LQB-S | F31: =Двигатели!B$2 -> 3 | G31: =Двигатели!C$2 -> 16 | H31: =Орудия!A$5 -> RP "Рейкастер" | I31: =Орудия!B$5 -> Кристалл | J31: =Орудия!C$5 -> 4 | K31: =Орудия!D$5 -> 4 | L31: =Орудия!E$5 -> 8/16' | M31: =B31-F31-J31 -> 13 | N31: =G31-D31-K31 -> 4
A32: =Генераторы!A$2 -> SG-2KT | B32: =Генераторы!B$2 -> 10 | C32: =Генераторы!C$2 -> 3+ | D32: =Генераторы!D$2 -> 2 | E32: =Двигатели!A$3 -> LQB-M | F32: =Двигатели!B$3 -> 6 | G32: =Двигатели!C$3 -> 18 | H32: =Орудия!A$5 -> RP "Рейкастер" | I32: =Орудия!B$5 -> Кристалл | J32: =Орудия!C$5 -> 4 | K32: =Орудия!D$5 -> 4 | L32: =Орудия!E$5 -> 8/16' | M32: =B32-F32-J32 -> 0 | N32: =G32-D32-K32 -> 12
A33: =Генераторы!A$3 -> SG-3KT | B33: =Генераторы!B$3 -> 15 | C33: =Генераторы!C$3 -> 3+ | D33: =Генераторы!D$3 -> 3 | E33: =Двигатели!A$3 -> LQB-M | F33: =Двигатели!B$3 -> 6 | G33: =Двигатели!C$3 -> 18 | H33: =Орудия!A$5 -> RP "Рейкастер" | I33: =Орудия!B$5 -> Кристалл | J33: =Орудия!C$5 -> 4 | K33: =Орудия!D$5 -> 4 | L33: =Орудия!E$5 -> 8/16' | M33: =B33-F33-J33 -> 5 | N33: =G33-D33-K33 -> 11
A34: =Генераторы!A$4 -> SG-8KT | B34: =Генераторы!B$4 -> 20 | C34: =Генераторы!C$4 -> 4+ | D34: =Генераторы!D$4 -> 8 | E34: =Двигатели!A$3 -> LQB-M | F34: =Двигатели!B$3 -> 6 | G34: =Двигатели!C$3 -> 18 | H34: =Орудия!A$5 -> RP "Рейкастер" | I34: =Орудия!B$5 -> Кристалл | J34: =Орудия!C$5 -> 4 | K34: =Орудия!D$5 -> 4 | L34: =Орудия!E$5 -> 8/16' | M34: =B34-F34-J34 -> 10 | N34: =G34-D34-K34 -> 6
A35: =Генераторы!A$2 -> SG-2KT | B35: =Генераторы!B$2 -> 10 | C35: =Генераторы!C$2 -> 3+ | D35: =Генераторы!D$2 -> 2 | E35: =Двигатели!A$4 -> LQB-L | F35: =Двигатели!B$4 -> 10 | G35: =Двигатели!C$4 -> 20 | H35: =Орудия!A$5 -> RP "Рейкастер" | I35: =Орудия!B$5 -> Кристалл | J35: =Орудия!C$5 -> 4 | K35: =Орудия!D$5 -> 4 | L35: =Орудия!E$5 -> 8/16' | M35: =B35-F35-J35 -> -4 | N35: =G35-D35-K35 -> 14
A36: =Генераторы!A$3 -> SG-3KT | B36: =Генераторы!B$3 -> 15 | C36: =Генераторы!C$3 -> 3+ | D36: =Генераторы!D$3 -> 3 | E36: =Двигатели!A$4 -> LQB-L | F36: =Двигатели!B$4 -> 10 | G36: =Двигатели!C$4 -> 20 | H36: =Орудия!A$5 -> RP "Рейкастер" | I36: =Орудия!B$5 -> Кристалл | J36: =Орудия!C$5 -> 4 | K36: =Орудия!D$5 -> 4 | L36: =Орудия!E$5 -> 8/16' | M36: =B36-F36-J36 -> 1 | N36: =G36-D36-K36 -> 13
A37: =Генераторы!A$4 -> SG-8KT | B37: =Генераторы!B$4 -> 20 | C37: =Генераторы!C$4 -> 4+ | D37: =Генераторы!D$4 -> 8 | E37: =Двигатели!A$4 -> LQB-L | F37: =Двигатели!B$4 -> 10 | G37: =Двигатели!C$4 -> 20 | H37: =Орудия!A$5 -> RP "Рейкастер" | I37: =Орудия!B$5 -> Кристалл | J37: =Орудия!C$5 -> 4 | K37: =Орудия!D$5 -> 4 | L37: =Орудия!E$5 -> 8/16' | M37: =B37-F37-J37 -> 6 | N37: =G37-D37-K37 -> 8
A38: =Генераторы!A$2 -> SG-2KT | B38: =Генераторы!B$2 -> 10 | C38: =Генераторы!C$2 -> 3+ | D38: =Генераторы!D$2 -> 2 | E38: =Двигатели!A$2 -> LQB-S | F38: =Двигатели!B$2 -> 3 | G38: =Двигатели!C$2 -> 16 | H38: =Орудия!A$6 -> HBT "Рубрик" | I38: =Орудия!B$6 -> тяж. Болт | J38: =Орудия!C$6 -> 10 | K38: =Орудия!D$6 -> 5 | L38: =Орудия!E$6 -> 18/32' | M38: =B38-F38-J38 -> -3 | N38: =G38-D38-K38 -> 9
A39: =Генераторы!A$3 -> SG-3KT | B39: =Генераторы!B$3 -> 15 | C39: =Генераторы!C$3 -> 3+ | D39: =Генераторы!D$3 -> 3 | E39: =Двигатели!A$2 -> LQB-S | F39: =Двигатели!B$2 -> 3 | G39: =Двигатели!C$2 -> 16 | H39: =Орудия!A$6 -> HBT "Рубрик" | I39: =Орудия!B$6 -> тяж. Болт | J39: =Орудия!C$6 -> 10 | K39: =Орудия!D$6 -> 5 | L39: =Орудия!E$6 -> 18/32' | M39: =B39-F39-J39 -> 2 | N39: =G39-D39-K39 -> 8
A40: =Генераторы!A$4 -> SG-8KT | B40: =Генераторы!B$4 -> 20 | C40: =Генераторы!C$4 -> 4+ | D40: =Генераторы!D$4 -> 8 | E40: =Двигатели!A$2 -> LQB-S | F40: =Двигатели!B$2 -> 3 | G40: =Двигатели!C$2 -> 16 | H40: =Орудия!A$6 -> HBT "Рубрик" | I40: =Орудия!B$6 -> тяж. Болт | J40: =Орудия!C$6 -> 10 | K40: =Орудия!D$6 -> 5 | L40: =Орудия!E$6 -> 18/32' | M40: =B40-F40-J40 -> 7 | N40: =G40-D40-K40 -> 3
...
